<?xml version="1.0" ?>
<!-- =================================================================================== -->
<!-- |    This document was autogenerated by xacro from steer_bot.urdf.xacro           | -->
<!-- |    EDITING THIS FILE BY HAND IS NOT RECOMMENDED                                 | -->
<!-- =================================================================================== -->
<!--
  Robot model adapted from https://github.com/CIR-KIT/steer_drive_ros/blob/kinetic-devel/steer_drive_controller/test/common/urdf/steerbot.xacro

  Modifications:
    Remove base_footprint link. Useful for navigation but not necessary for a simple example.
    Added materials for URDF
    Updated inertials

  Geometry:
    The Ackermann steering controllers require the longitudinal
    separation between the front and back wheel axes and the
    lateral separation between the left and right front steering axes.
    
    For this model:
    wheel_separation_h = base_length - 2 * axle_offset = 0.4
    wheel_separation_w = base_width + 2 * axle_offset = 0.4
-->
<robot name="steer_bot">
  <material name="red">
    <color rgba="0.8 0 0 1"/>
  </material>
  <material name="green">
    <color rgba="0 0.8 0 1"/>
  </material>
  <material name="blue">
    <color rgba="0 0 0.8 1"/>
  </material>
  <material name="yellow">
    <color rgba="0.8 0.8 0 1"/>
  </material>
  <material name="orange">
    <color rgba="0.8 0.25 0 1"/>
  </material>
  <material name="black">
    <color rgba="0 0 0 1"/>
  </material>
  <material name="dark_gray">
    <color rgba="0.5 0.5 0.5 1"/>
  </material>
  <material name="gray">
    <color rgba="0.753 0.753 0.753 1"/>
  </material>
  <material name="silver">
    <color rgba="0.88 0.88 0.88 1"/>
  </material>
  <material name="white">
    <color rgba="1 1 1 1"/>
  </material>
  <!-- Gazebo plugins -->
  <gazebo>
    <!-- Load ros_control plugin using the steer_bot_hardware_gazebo
    implementation of the hardware_interface::RobotHW -->
    <plugin filename="libgazebo_ros_control.so" name="gazebo_ros_control">
      <robotNamespace>/steer_bot</robotNamespace>
      <robotSimType>steer_bot_hardware_gazebo/SteerBotHardwareGazebo</robotSimType>
      <legacyModeNS>false</legacyModeNS>
    </plugin>
  </gazebo>
  <!-- Base link -->
  <link name="base_link">
    <visual>
      <origin rpy="0 0 0" xyz="0 0 0"/>
      <geometry>
        <box size="0.2 0.09 0.05"/>
      </geometry>
      <material name="green"/>
    </visual>
    <collision>
      <origin rpy="0 0 0" xyz="0 0 0"/>
      <geometry>
        <box size="0.2 0.09 0.05"/>
      </geometry>
    </collision>
    <inertial>
      <origin rpy="0 0 0" xyz="0 0 0"/>
      <mass value="2.5"/>
      <inertia ixx="0.0022083333333333334" ixy="0.0" ixz="0.0" iyy="0.008854166666666668" iyz="0.0" izz="0.010020833333333335"/>
    </inertial>
  </link>
  <link name="front_steer_link">
    <visual>
      <origin rpy="0 0 0" xyz="0 0 0"/>
      <geometry>
        <cylinder length="0.02" radius="0.05"/>
      </geometry>
      <material name="yellow"/>
    </visual>
    <inertial>
      <origin rpy="0 0 0" xyz="0 0 0"/>
      <mass value="1"/>
      <inertia ixx="0.0006583333333333334" ixy="0.0" ixz="0.0" iyy="0.0006583333333333334" iyz="0.0" izz="0.0012500000000000002"/>
    </inertial>
  </link>
  <joint name="front_steer_joint" type="revolute">
    <parent link="base_link"/>
    <child link="front_steer_link"/>
    <origin rpy="0 0 0" xyz="0.08750000000000001 0 0.079"/>
    <axis xyz="0 0 1"/>
    <limit effort="10.0" lower="-3.141592653589793" upper="3.141592653589793" velocity="5.0"/>
  </joint>
  <transmission name="front_steer_joint_trans">
    <type>transmission_interface/SimpleTransmission</type>
    <actuator name="front_steer_joint_motor">
      <mechanicalReduction>1</mechanicalReduction>
      <hardwareInterface>hardware_interface/PositionJointInterface</hardwareInterface>
    </actuator>
    <joint name="front_steer_joint">
      <hardwareInterface>hardware_interface/PositionJointInterface</hardwareInterface>
    </joint>
  </transmission>
  <gazebo reference="front_steer_link">
    <material>Gazebo/Yellow</material>
  </gazebo>
  <link name="rear_wheel_link">
    <visual>
      <origin rpy="0 0 0" xyz="0 0 0"/>
      <geometry>
        <cylinder length="0.0135" radius="0.0085"/>
      </geometry>
      <material name="yellow"/>
    </visual>
    <inertial>
      <origin rpy="0 0 0" xyz="0 0 0"/>
      <mass value="0.015625"/>
      <inertia ixx="5.1953125e-07" ixy="0.0" ixz="0.0" iyy="5.1953125e-07" iyz="0.0" izz="5.644531250000001e-07"/>
    </inertial>
  </link>
  <joint name="rear_wheel_joint" type="continuous">
    <parent link="base_link"/>
    <child link="rear_wheel_link"/>
    <origin rpy="-1.5707963267948966 0 0" xyz="-0.08750000000000001 0 0"/>
    <axis xyz="0 0 1"/>
  </joint>
  <transmission name="rear_wheel_joint_trans">
    <type>transmission_interface/SimpleTransmission</type>
    <actuator name="rear_wheel_joint_motor">
      <mechanicalReduction>1</mechanicalReduction>
      <hardwareInterface>hardware_interface/VelocityJointInterface</hardwareInterface>
    </actuator>
    <joint name="rear_wheel_joint">
      <hardwareInterface>hardware_interface/VelocityJointInterface</hardwareInterface>
    </joint>
  </transmission>
  <gazebo reference="rear_wheel_link">
    <material>Gazebo/Yellow</material>
  </gazebo>
  <link name="front_right_steer_link">
    <visual>
      <origin rpy="0 0 0" xyz="0 0 0"/>
      <geometry>
        <cylinder length="0.02" radius="0.05"/>
      </geometry>
      <material name="blue"/>
    </visual>
    <inertial>
      <origin rpy="0 0 0" xyz="0 0 0"/>
      <mass value="1"/>
      <inertia ixx="0.0006583333333333334" ixy="0.0" ixz="0.0" iyy="0.0006583333333333334" iyz="0.0" izz="0.0012500000000000002"/>
    </inertial>
  </link>
  <joint name="front_right_steer_joint" type="revolute">
    <parent link="base_link"/>
    <child link="front_right_steer_link"/>
    <origin rpy="0 0 0" xyz="0.08750000000000001 -0.057499999999999996 0.079"/>
    <axis xyz="0 0 1"/>
    <limit effort="10.0" lower="-0.7853981633974483" upper="0.7853981633974483" velocity="5.0"/>
  </joint>
  <link name="front_right_wheel_link">
    <visual>
      <origin rpy="0 0 0" xyz="0 0 0"/>
      <geometry>
        <cylinder length="0.027" radius="0.034"/>
      </geometry>
      <material name="red"/>
    </visual>
    <collision>
      <origin rpy="0 0 0" xyz="0 0 0"/>
      <geometry>
        <cylinder length="0.027" radius="0.034"/>
      </geometry>
    </collision>
    <inertial>
      <origin rpy="0 0 0" xyz="0 0 0"/>
      <mass value="0.5"/>
      <inertia ixx="0.000174875" ixy="0.0" ixz="0.0" iyy="0.000174875" iyz="0.0" izz="0.00028900000000000003"/>
    </inertial>
  </link>
  <joint name="front_right_wheel_joint" type="continuous">
    <parent link="front_right_steer_link"/>
    <child link="front_right_wheel_link"/>
    <origin rpy="-1.5707963267948966 0 0" xyz="0 0 -0.079"/>
    <axis xyz="0 0 1"/>
  </joint>
  <transmission name="front_right_steer_joint_trans">
    <type>transmission_interface/SimpleTransmission</type>
    <actuator name="front_right_steer_joint_motor">
      <mechanicalReduction>1</mechanicalReduction>
      <hardwareInterface>hardware_interface/PositionJointInterface</hardwareInterface>
    </actuator>
    <joint name="front_right_steer_joint">
      <hardwareInterface>hardware_interface/PositionJointInterface</hardwareInterface>
    </joint>
  </transmission>
  <transmission name="front_right_wheel_joint_trans">
    <type>transmission_interface/SimpleTransmission</type>
    <actuator name="front_right_wheel_joint_motor">
      <mechanicalReduction>1</mechanicalReduction>
      <hardwareInterface>hardware_interface/VelocityJointInterface</hardwareInterface>
    </actuator>
    <joint name="front_right_wheel_joint">
      <hardwareInterface>hardware_interface/VelocityJointInterface</hardwareInterface>
    </joint>
  </transmission>
  <gazebo reference="front_right_steer_link">
    <material>Gazebo/Blue</material>
  </gazebo>
  <gazebo reference="front_right_wheel_link">
    <material>Gazebo/Red</material>
  </gazebo>
  <link name="front_left_steer_link">
    <visual>
      <origin rpy="0 0 0" xyz="0 0 0"/>
      <geometry>
        <cylinder length="0.02" radius="0.05"/>
      </geometry>
      <material name="blue"/>
    </visual>
    <inertial>
      <origin rpy="0 0 0" xyz="0 0 0"/>
      <mass value="1"/>
      <inertia ixx="0.0006583333333333334" ixy="0.0" ixz="0.0" iyy="0.0006583333333333334" iyz="0.0" izz="0.0012500000000000002"/>
    </inertial>
  </link>
  <joint name="front_left_steer_joint" type="revolute">
    <parent link="base_link"/>
    <child link="front_left_steer_link"/>
    <origin rpy="0 0 0" xyz="0.08750000000000001 0.057499999999999996 0.079"/>
    <axis xyz="0 0 1"/>
    <limit effort="10.0" lower="-0.7853981633974483" upper="0.7853981633974483" velocity="5.0"/>
  </joint>
  <link name="front_left_wheel_link">
    <visual>
      <origin rpy="0 0 0" xyz="0 0 0"/>
      <geometry>
        <cylinder length="0.027" radius="0.034"/>
      </geometry>
      <material name="red"/>
    </visual>
    <collision>
      <origin rpy="0 0 0" xyz="0 0 0"/>
      <geometry>
        <cylinder length="0.027" radius="0.034"/>
      </geometry>
    </collision>
    <inertial>
      <origin rpy="0 0 0" xyz="0 0 0"/>
      <mass value="0.5"/>
      <inertia ixx="0.000174875" ixy="0.0" ixz="0.0" iyy="0.000174875" iyz="0.0" izz="0.00028900000000000003"/>
    </inertial>
  </link>
  <joint name="front_left_wheel_joint" type="continuous">
    <parent link="front_left_steer_link"/>
    <child link="front_left_wheel_link"/>
    <origin rpy="-1.5707963267948966 0 0" xyz="0 0 -0.079"/>
    <axis xyz="0 0 1"/>
  </joint>
  <transmission name="front_left_steer_joint_trans">
    <type>transmission_interface/SimpleTransmission</type>
    <actuator name="front_left_steer_joint_motor">
      <mechanicalReduction>1</mechanicalReduction>
      <hardwareInterface>hardware_interface/PositionJointInterface</hardwareInterface>
    </actuator>
    <joint name="front_left_steer_joint">
      <hardwareInterface>hardware_interface/PositionJointInterface</hardwareInterface>
    </joint>
  </transmission>
  <transmission name="front_left_wheel_joint_trans">
    <type>transmission_interface/SimpleTransmission</type>
    <actuator name="front_left_wheel_joint_motor">
      <mechanicalReduction>1</mechanicalReduction>
      <hardwareInterface>hardware_interface/VelocityJointInterface</hardwareInterface>
    </actuator>
    <joint name="front_left_wheel_joint">
      <hardwareInterface>hardware_interface/VelocityJointInterface</hardwareInterface>
    </joint>
  </transmission>
  <gazebo reference="front_left_steer_link">
    <material>Gazebo/Blue</material>
  </gazebo>
  <gazebo reference="front_left_wheel_link">
    <material>Gazebo/Red</material>
  </gazebo>
  <link name="rear_right_wheel_link">
    <visual>
      <origin rpy="0 0 0" xyz="0 0 0"/>
      <geometry>
        <cylinder length="0.027" radius="0.034"/>
      </geometry>
      <material name="red"/>
    </visual>
    <collision>
      <origin rpy="0 0 0" xyz="0 0 0"/>
      <geometry>
        <cylinder length="0.027" radius="0.034"/>
      </geometry>
    </collision>
    <inertial>
      <origin rpy="0 0 0" xyz="0 0 0"/>
      <mass value="0.5"/>
      <inertia ixx="0.000174875" ixy="0.0" ixz="0.0" iyy="0.000174875" iyz="0.0" izz="0.00028900000000000003"/>
    </inertial>
  </link>
  <joint name="rear_right_wheel_joint" type="continuous">
    <parent link="base_link"/>
    <child link="rear_right_wheel_link"/>
    <origin rpy="-1.5707963267948966 0 0" xyz="-0.08750000000000001 -0.057499999999999996 0"/>
    <axis xyz="0 0 1"/>
  </joint>
  <transmission name="rear_right_wheel_joint_trans">
    <type>transmission_interface/SimpleTransmission</type>
    <actuator name="rear_right_wheel_joint_motor">
      <mechanicalReduction>1</mechanicalReduction>
      <hardwareInterface>hardware_interface/VelocityJointInterface</hardwareInterface>
    </actuator>
    <joint name="rear_right_wheel_joint">
      <hardwareInterface>hardware_interface/VelocityJointInterface</hardwareInterface>
    </joint>
  </transmission>
  <gazebo reference="rear_right_wheel_link">
    <material>Gazebo/Red</material>
  </gazebo>
  <link name="rear_left_wheel_link">
    <visual>
      <origin rpy="0 0 0" xyz="0 0 0"/>
      <geometry>
        <cylinder length="0.027" radius="0.034"/>
      </geometry>
      <material name="red"/>
    </visual>
    <collision>
      <origin rpy="0 0 0" xyz="0 0 0"/>
      <geometry>
        <cylinder length="0.027" radius="0.034"/>
      </geometry>
    </collision>
    <inertial>
      <origin rpy="0 0 0" xyz="0 0 0"/>
      <mass value="0.5"/>
      <inertia ixx="0.000174875" ixy="0.0" ixz="0.0" iyy="0.000174875" iyz="0.0" izz="0.00028900000000000003"/>
    </inertial>
  </link>
  <joint name="rear_left_wheel_joint" type="continuous">
    <parent link="base_link"/>
    <child link="rear_left_wheel_link"/>
    <origin rpy="-1.5707963267948966 0 0" xyz="-0.08750000000000001 0.057499999999999996 0"/>
    <axis xyz="0 0 1"/>
  </joint>
  <transmission name="rear_left_wheel_joint_trans">
    <type>transmission_interface/SimpleTransmission</type>
    <actuator name="rear_left_wheel_joint_motor">
      <mechanicalReduction>1</mechanicalReduction>
      <hardwareInterface>hardware_interface/VelocityJointInterface</hardwareInterface>
    </actuator>
    <joint name="rear_left_wheel_joint">
      <hardwareInterface>hardware_interface/VelocityJointInterface</hardwareInterface>
    </joint>
  </transmission>
  <gazebo reference="rear_left_wheel_link">
    <material>Gazebo/Red</material>
  </gazebo>
  <!-- Camera Link -->
  <link name="camera_link">
    <visual>
      <origin rpy="0 0 0" xyz="0 0 0"/>
      <geometry>
        <box size="0.03 0.03 0.03"/>
      </geometry>
      <material name="red"/>
    </visual>
    <collision>
      <origin rpy="0 0 0" xyz="0 0 0"/>
      <geometry>
        <box size="0.03 0.03 0.03"/>
      </geometry>
    </collision>
    <inertial>
      <origin rpy="0 0 0" xyz="0 0 0"/>
      <mass value="0.1"/>
      <inertia ixx="1.5e-05" ixy="0.0" ixz="0.0" iyy="1.5e-05" iyz="0.0" izz="1.5e-05"/>
    </inertial>
  </link>
  <joint name="camera_joint" type="fixed">
    <parent link="base_link"/>
    <child link="camera_link"/>
    <origin rpy="0 0 0" xyz="0.1 0 0.025"/>
  </joint>
  <!-- Ultrasonic Sensor Links -->
  <link name="ultrasonic_front_link">
    <visual>
      <origin rpy="0 0 0" xyz="0 0 0"/>
      <geometry>
        <box size="0.02 0.02 0.02"/>
      </geometry>
      <material name="blue"/>
    </visual>
    <collision>
      <origin rpy="0 0 0" xyz="0 0 0"/>
      <geometry>
        <box size="0.02 0.02 0.02"/>
      </geometry>
    </collision>
    <inertial>
      <origin rpy="0 0 0" xyz="0 0 0"/>
      <mass value="0.05"/>
      <inertia ixx="3.3333333333333337e-06" ixy="0.0" ixz="0.0" iyy="3.3333333333333337e-06" iyz="0.0" izz="3.3333333333333337e-06"/>
    </inertial>
  </link>
  <joint name="ultrasonic_front_joint" type="fixed">
    <parent link="base_link"/>
    <child link="ultrasonic_front_link"/>
    <origin rpy="0 1.5707963267948966 0" xyz="0.1 0 0.005000000000000001"/>
  </joint>
  <link name="ultrasonic_rear_link">
    <visual>
      <origin rpy="0 0 0" xyz="0 0 0"/>
      <geometry>
        <box size="0.02 0.02 0.02"/>
      </geometry>
      <material name="blue"/>
    </visual>
    <collision>
      <origin rpy="0 0 0" xyz="0 0 0"/>
      <geometry>
        <box size="0.02 0.02 0.02"/>
      </geometry>
    </collision>
    <inertial>
      <origin rpy="0 0 0" xyz="0 0 0"/>
      <mass value="0.05"/>
      <inertia ixx="3.3333333333333337e-06" ixy="0.0" ixz="0.0" iyy="3.3333333333333337e-06" iyz="0.0" izz="3.3333333333333337e-06"/>
    </inertial>
  </link>
  <joint name="ultrasonic_rear_joint" type="fixed">
    <parent link="base_link"/>
    <child link="ultrasonic_rear_link"/>
    <origin rpy="0 -1.5707963267948966 0" xyz="-0.1 0 0.005000000000000001"/>
  </joint>
  <link name="ultrasonic_right_link">
    <visual>
      <origin rpy="0 0 0" xyz="0 0 0"/>
      <geometry>
        <box size="0.02 0.02 0.02"/>
      </geometry>
      <material name="blue"/>
    </visual>
    <collision>
      <origin rpy="0 0 0" xyz="0 0 0"/>
      <geometry>
        <box size="0.02 0.02 0.02"/>
      </geometry>
    </collision>
    <inertial>
      <origin rpy="0 0 0" xyz="0 0 0"/>
      <mass value="0.05"/>
      <inertia ixx="3.3333333333333337e-06" ixy="0.0" ixz="0.0" iyy="3.3333333333333337e-06" iyz="0.0" izz="3.3333333333333337e-06"/>
    </inertial>
  </link>
  <joint name="ultrasonic_right_joint" type="fixed">
    <parent link="base_link"/>
    <child link="ultrasonic_right_link"/>
    <origin rpy="0 0 -1.5707963267948966" xyz="0 -0.045 0.005000000000000001"/>
  </joint>
  <link name="ultrasonic_left_link">
    <visual>
      <origin rpy="0 0 0" xyz="0 0 0"/>
      <geometry>
        <box size="0.02 0.02 0.02"/>
      </geometry>
      <material name="blue"/>
    </visual>
    <collision>
      <origin rpy="0 0 0" xyz="0 0 0"/>
      <geometry>
        <box size="0.02 0.02 0.02"/>
      </geometry>
    </collision>
    <inertial>
      <origin rpy="0 0 0" xyz="0 0 0"/>
      <mass value="0.05"/>
      <inertia ixx="3.3333333333333337e-06" ixy="0.0" ixz="0.0" iyy="3.3333333333333337e-06" iyz="0.0" izz="3.3333333333333337e-06"/>
    </inertial>
  </link>
  <joint name="ultrasonic_left_joint" type="fixed">
    <parent link="base_link"/>
    <child link="ultrasonic_left_link"/>
    <origin rpy="0 0 1.5707963267948966" xyz="0 0.045 0.005000000000000001"/>
  </joint>
  <!-- Colour -->
  <gazebo reference="base_link">
    <material>Gazebo/Green</material>
  </gazebo>
  <!-- Add materials for Gazebo -->
  <gazebo reference="camera_link">
    <material>Gazebo/Red</material>
  </gazebo>
  <gazebo reference="ultrasonic_front_link">
    <material>Gazebo/Blue</material>
  </gazebo>
  <gazebo reference="ultrasonic_rear_link">
    <material>Gazebo/Blue</material>
  </gazebo>
  <gazebo reference="ultrasonic_right_link">
    <material>Gazebo/Blue</material>
  </gazebo>
  <gazebo reference="ultrasonic_left_link">
    <material>Gazebo/Blue</material>
  </gazebo>
</robot>
